<?xml version="1.0"?>
<robot name="holly">

    <link name="/base_link">
        <visual>
            <geometry>
                <box size="0.505 0.27 0.02"/>
            </geometry>
            <material name="grey" />
            <origin rpy="0 0 0" xyz="0 0 0.2" />
        </visual>
    </link>

    <link name="/laserscan_frame"></link>

    <joint name="base_to_laserscan_sensor" type="fixed">
        <parent link="/base_link" />
        <child link="/laserscan_frame" />
        <origin xyz="0.25 0.0 0.0" rpy="0 0 0" />
    </joint>

    <joint name="base_to_kinect_sensor" type="fixed">
        <parent link="/base_link" />
        <child link="/kinect_link" />
        <origin xyz="0.25 0.0 0.38" rpy="0 0.349066 0" />
    </joint>

    <link name="/kinect_link">
        <visual>
            <geometry>
                <box size="0.064 0.28 0.0381" />
            </geometry>
            <material name="black" />

        </visual>
        <inertial>
            <mass value="0.0001" />
            <origin xyz="0 0 0" />
            <inertia ixx="0.0001" ixy="0.0" ixz="0.0" iyy="0.0001" iyz="0.0" izz="0.0001" />
        </inertial>
    </link>

    <joint name="kinect_depth_joint" type="fixed">
        <origin xyz="0 -0.0125 0" rpy="0 0 0" />
        <parent link="/kinect_link" />
        <child link="/kinect_depth_frame" />
    </joint>

    <link name="/kinect_depth_frame">
        <inertial>
            <mass value="0.0001" />
            <origin xyz="0 0 0" />
            <inertia ixx="0.0001" ixy="0.0" ixz="0.0" iyy="0.0001" iyz="0.0" izz="0.0001" />
        </inertial>
    </link>

    <joint name="depth_optical_joint" type="fixed">
        <origin xyz="0 0.025 0" rpy="-1.570795 0 -1.570795" />
        <parent link="/kinect_depth_frame" />
        <child link="/kinect_depth_optical_frame" />
    </joint>

    <link name="/kinect_depth_optical_frame">
        <inertial>
            <mass value="0.0001" />
            <origin xyz="0 0 0" />
            <inertia ixx="0.0001" ixy="0.0" ixz="0.0" iyy="0.0001" iyz="0.0" izz="0.0001" />
        </inertial>
    </link>

    <material name="white">
        <color rgba="1 1 1 1"/>
    </material>
    <material name="black">
        <color rgba="0 0 0 1"/>
    </material>
    <material name="grey">
        <color rgba="0.5 0.5 0.5 1"/>
    </material>


    <link name="/wheel1">
        <visual>
            <geometry>
                <cylinder radius="0.06" length="0.06"/>
            </geometry>
            <material name="black" />
        </visual>
    </link>

    <link name="/wheel2">
        <visual>
            <geometry>
                <cylinder radius="0.06" length="0.06"/>
            </geometry>
            <material name="black" />
        </visual>
    </link>

    <link name="/wheel3">
        <visual>
            <geometry>
                <cylinder radius="0.06" length="0.06"/>
            </geometry>
            <material name="black" />
        </visual>
    </link>

    <link name="/wheel4">
        <visual>
            <geometry>
                <cylinder radius="0.06" length="0.06"/>
            </geometry>
            <material name="black" />
        </visual>
    </link>

    <link name="/wheel5">
        <visual>
            <geometry>
                <cylinder radius="0.06" length="0.06"/>
            </geometry>
            <material name="black" />
        </visual>
    </link>

    <link name="/wheel6">
        <visual>
            <geometry>
                <cylinder radius="0.06" length="0.06"/>
            </geometry>
            <material name="black" />
        </visual>
    </link>

    <link name="/motor1">
        <visual>
            <geometry>
                <cylinder radius="0.016" length="0.075"/>
            </geometry>
            <material name="grey" />
            <origin rpy="0 0 0" xyz="0 0 0.08" />
        </visual>
    </link>

    <link name="/motor2">
        <visual>
            <geometry>
                <cylinder radius="0.016" length="0.075"/>
            </geometry>
            <material name="grey" />
            <origin rpy="0 0 0" xyz="0 0 0.08" />
        </visual>
    </link>

    <link name="/motor3">
        <visual>
            <geometry>
                <cylinder radius="0.016" length="0.075"/>
            </geometry>
            <material name="grey" />
            <origin rpy="0 0 0" xyz="0 0 0.08" />
        </visual>
    </link>

    <link name="/motor4">
        <visual>
            <geometry>
                <cylinder radius="0.016" length="0.075"/>
            </geometry>
            <material name="grey" />
            <origin rpy="0 0 0" xyz="0 0 0.08" />
        </visual>
    </link>

    <link name="/motor5">
        <visual>
            <geometry>
                <cylinder radius="0.016" length="0.075"/>
            </geometry>
            <material name="grey" />
            <origin rpy="0 0 0" xyz="0 0 0.08" />
        </visual>
    </link>

    <link name="/motor6">
        <visual>
            <geometry>
                <cylinder radius="0.016" length="0.075"/>
            </geometry>
            <material name="grey" />
            <origin rpy="0 0 0" xyz="0 0 0.08" />
        </visual>
    </link>

    <joint name="base_to_motor1" type="continuous">
        <parent link="/base_link" />
        <child link="/motor1" />
        <axis xyz="0 1 0"/>
        <origin rpy="1.570895 0 0" xyz="0 0.17 0.06" />
    </joint>

    <joint name="base_to_motor2" type="continuous">
        <parent link="/base_link" />
        <child link="/motor2" />
        <axis xyz="0 1 0"/>
        <origin rpy="1.570895 3.14159 0" xyz="0 -0.17 0.06" />
    </joint>

    <joint name="base_to_motor3" type="continuous">
        <parent link="/base_link" />
        <child link="/motor3" />
        <axis xyz="0 1 0"/>
        <origin rpy="1.570895 3.14159 0" xyz="0.23 -0.17 0.06" />
    </joint>

    <joint name="base_to_motor4" type="continuous">
        <parent link="/base_link" />
        <child link="/motor4" />
        <axis xyz="0 1 0"/>
        <origin rpy="1.570895 0 0" xyz="0.23 0.17 0.06" />
    </joint>

    <joint name="base_to_motor5" type="continuous">
        <parent link="/base_link" />
        <child link="/motor5" />
        <axis xyz="0 1 0"/>
        <origin rpy="1.570895 3.14159 0" xyz="-0.23 -0.17 0.06" />
    </joint>

    <joint name="base_to_motor6" type="continuous">
        <parent link="/base_link" />
        <child link="/motor6" />
        <axis xyz="0 1 0"/>
        <origin rpy="1.570895 0 0" xyz="-0.23 0.17 0.06" />
    </joint>

    <joint name="motor_to_wheel1" type="continuous">
        <parent link="/motor1" />
        <child link="/wheel1" />
        <axis xyz="0 0 1"/>
        <origin rpy="0 0 0" xyz="0 0 0" />
    </joint>

    <joint name="motor_to_wheel2" type="continuous">
        <parent link="/motor2" />
        <child link="/wheel2" />
        <axis xyz="0 0 1"/>
        <origin rpy="0 0 0" xyz="0 0 0" />
    </joint>

    <joint name="motor_to_wheel3" type="continuous">
        <parent link="/motor3" />
        <child link="/wheel3" />
        <axis xyz="0 0 1"/>
        <origin rpy="0 0 0" xyz="0 0 0" />
    </joint>

    <joint name="motor_to_wheel4" type="continuous">
        <parent link="/motor4" />
        <child link="/wheel4" />
        <axis xyz="0 0 1"/>
        <origin rpy="0 0 0" xyz="0 0 0" />
    </joint>

    <joint name="motor_to_wheel5" type="continuous">
        <parent link="/motor5" />
        <child link="/wheel5" />
        <axis xyz="0 0 1"/>
        <origin rpy="0 0 0" xyz="0 0 0" />
    </joint>

    <joint name="motor_to_wheel6" type="continuous">
        <parent link="/motor6" />
        <child link="/wheel6" />
        <axis xyz="0 0 1"/>
        <origin rpy="0 0 0" xyz="0 0 0" />
    </joint>

</robot>